Mon, 29 Oct 2018 14:22:41 simplelogger.py[line:28] ERROR Project matching query does not exist.
Traceback (most recent call last):
  File "/Users/ethan/Documents/OneDrive/coding.net/doraemon_nirvana_lte/doraemon/model_managers/project_model_manager.py", line 198, in get
    result=super(ProjectManager,self).get_queryset().get(id=projectid)
  File "/Library/Frameworks/Python.framework/Versions/3.5/lib/python3.5/site-packages/django/db/models/query.py", line 403, in get
    self.model._meta.object_name
doraemon.project.models.DoesNotExist: Project matching query does not exist.
Mon, 29 Oct 2018 14:22:41 simplelogger.py[line:28] ERROR Project matching query does not exist.
Traceback (most recent call last):
  File "/Users/ethan/Documents/OneDrive/coding.net/doraemon_nirvana_lte/doraemon/model_managers/project_model_manager.py", line 198, in get
    result=super(ProjectManager,self).get_queryset().get(id=projectid)
  File "/Library/Frameworks/Python.framework/Versions/3.5/lib/python3.5/site-packages/django/db/models/query.py", line 403, in get
    self.model._meta.object_name
doraemon.project.models.DoesNotExist: Project matching query does not exist.
Mon, 29 Oct 2018 14:22:41 simplelogger.py[line:28] ERROR Project matching query does not exist.
Traceback (most recent call last):
  File "/Users/ethan/Documents/OneDrive/coding.net/doraemon_nirvana_lte/doraemon/model_managers/project_model_manager.py", line 198, in get
    result=super(ProjectManager,self).get_queryset().get(id=projectid)
  File "/Library/Frameworks/Python.framework/Versions/3.5/lib/python3.5/site-packages/django/db/models/query.py", line 403, in get
    self.model._meta.object_name
doraemon.project.models.DoesNotExist: Project matching query does not exist.
Mon, 29 Oct 2018 14:22:41 simplelogger.py[line:28] ERROR Project matching query does not exist.
Traceback (most recent call last):
  File "/Users/ethan/Documents/OneDrive/coding.net/doraemon_nirvana_lte/doraemon/model_managers/project_model_manager.py", line 198, in get
    result=super(ProjectManager,self).get_queryset().get(id=projectid)
  File "/Library/Frameworks/Python.framework/Versions/3.5/lib/python3.5/site-packages/django/db/models/query.py", line 403, in get
    self.model._meta.object_name
doraemon.project.models.DoesNotExist: Project matching query does not exist.
Mon, 29 Oct 2018 14:22:41 simplelogger.py[line:28] ERROR Project matching query does not exist.
Traceback (most recent call last):
  File "/Users/ethan/Documents/OneDrive/coding.net/doraemon_nirvana_lte/doraemon/model_managers/project_model_manager.py", line 198, in get
    result=super(ProjectManager,self).get_queryset().get(id=projectid)
  File "/Library/Frameworks/Python.framework/Versions/3.5/lib/python3.5/site-packages/django/db/models/query.py", line 403, in get
    self.model._meta.object_name
doraemon.project.models.DoesNotExist: Project matching query does not exist.
Mon, 29 Oct 2018 14:22:41 simplelogger.py[line:28] ERROR Project matching query does not exist.
Traceback (most recent call last):
  File "/Users/ethan/Documents/OneDrive/coding.net/doraemon_nirvana_lte/doraemon/model_managers/project_model_manager.py", line 198, in get
    result=super(ProjectManager,self).get_queryset().get(id=projectid)
  File "/Library/Frameworks/Python.framework/Versions/3.5/lib/python3.5/site-packages/django/db/models/query.py", line 403, in get
    self.model._meta.object_name
doraemon.project.models.DoesNotExist: Project matching query does not exist.
Mon, 29 Oct 2018 14:22:41 simplelogger.py[line:28] ERROR Project matching query does not exist.
Traceback (most recent call last):
  File "/Users/ethan/Documents/OneDrive/coding.net/doraemon_nirvana_lte/doraemon/model_managers/project_model_manager.py", line 198, in get
    result=super(ProjectManager,self).get_queryset().get(id=projectid)
  File "/Library/Frameworks/Python.framework/Versions/3.5/lib/python3.5/site-packages/django/db/models/query.py", line 403, in get
    self.model._meta.object_name
doraemon.project.models.DoesNotExist: Project matching query does not exist.
Mon, 29 Oct 2018 14:22:41 simplelogger.py[line:28] ERROR Project matching query does not exist.
Traceback (most recent call last):
  File "/Users/ethan/Documents/OneDrive/coding.net/doraemon_nirvana_lte/doraemon/model_managers/project_model_manager.py", line 198, in get
    result=super(ProjectManager,self).get_queryset().get(id=projectid)
  File "/Library/Frameworks/Python.framework/Versions/3.5/lib/python3.5/site-packages/django/db/models/query.py", line 403, in get
    self.model._meta.object_name
doraemon.project.models.DoesNotExist: Project matching query does not exist.
Mon, 29 Oct 2018 14:22:41 simplelogger.py[line:28] ERROR Project matching query does not exist.
Traceback (most recent call last):
  File "/Users/ethan/Documents/OneDrive/coding.net/doraemon_nirvana_lte/doraemon/model_managers/project_model_manager.py", line 198, in get
    result=super(ProjectManager,self).get_queryset().get(id=projectid)
  File "/Library/Frameworks/Python.framework/Versions/3.5/lib/python3.5/site-packages/django/db/models/query.py", line 403, in get
    self.model._meta.object_name
doraemon.project.models.DoesNotExist: Project matching query does not exist.
Mon, 29 Oct 2018 14:22:41 simplelogger.py[line:28] ERROR Project matching query does not exist.
Traceback (most recent call last):
  File "/Users/ethan/Documents/OneDrive/coding.net/doraemon_nirvana_lte/doraemon/model_managers/project_model_manager.py", line 198, in get
    result=super(ProjectManager,self).get_queryset().get(id=projectid)
  File "/Library/Frameworks/Python.framework/Versions/3.5/lib/python3.5/site-packages/django/db/models/query.py", line 403, in get
    self.model._meta.object_name
doraemon.project.models.DoesNotExist: Project matching query does not exist.
Mon, 29 Oct 2018 14:22:41 simplelogger.py[line:28] ERROR Project matching query does not exist.
Traceback (most recent call last):
  File "/Users/ethan/Documents/OneDrive/coding.net/doraemon_nirvana_lte/doraemon/model_managers/project_model_manager.py", line 198, in get
    result=super(ProjectManager,self).get_queryset().get(id=projectid)
  File "/Library/Frameworks/Python.framework/Versions/3.5/lib/python3.5/site-packages/django/db/models/query.py", line 403, in get
    self.model._meta.object_name
doraemon.project.models.DoesNotExist: Project matching query does not exist.
Mon, 29 Oct 2018 17:09:53 simplelogger.py[line:28] ERROR Project matching query does not exist.
Traceback (most recent call last):
  File "/Users/ethan/Documents/OneDrive/coding.net/doraemon_nirvana_lte/doraemon/model_managers/project_model_manager.py", line 198, in get
    result=super(ProjectManager,self).get_queryset().get(id=projectid)
  File "/Library/Frameworks/Python.framework/Versions/3.5/lib/python3.5/site-packages/django/db/models/query.py", line 403, in get
    self.model._meta.object_name
doraemon.project.models.DoesNotExist: Project matching query does not exist.
Mon, 29 Oct 2018 17:09:53 simplelogger.py[line:28] ERROR Project matching query does not exist.
Traceback (most recent call last):
  File "/Users/ethan/Documents/OneDrive/coding.net/doraemon_nirvana_lte/doraemon/model_managers/project_model_manager.py", line 198, in get
    result=super(ProjectManager,self).get_queryset().get(id=projectid)
  File "/Library/Frameworks/Python.framework/Versions/3.5/lib/python3.5/site-packages/django/db/models/query.py", line 403, in get
    self.model._meta.object_name
doraemon.project.models.DoesNotExist: Project matching query does not exist.
Mon, 29 Oct 2018 17:09:53 simplelogger.py[line:28] ERROR Project matching query does not exist.
Traceback (most recent call last):
  File "/Users/ethan/Documents/OneDrive/coding.net/doraemon_nirvana_lte/doraemon/model_managers/project_model_manager.py", line 198, in get
    result=super(ProjectManager,self).get_queryset().get(id=projectid)
  File "/Library/Frameworks/Python.framework/Versions/3.5/lib/python3.5/site-packages/django/db/models/query.py", line 403, in get
    self.model._meta.object_name
doraemon.project.models.DoesNotExist: Project matching query does not exist.
Mon, 29 Oct 2018 17:09:53 simplelogger.py[line:28] ERROR Project matching query does not exist.
Traceback (most recent call last):
  File "/Users/ethan/Documents/OneDrive/coding.net/doraemon_nirvana_lte/doraemon/model_managers/project_model_manager.py", line 198, in get
    result=super(ProjectManager,self).get_queryset().get(id=projectid)
  File "/Library/Frameworks/Python.framework/Versions/3.5/lib/python3.5/site-packages/django/db/models/query.py", line 403, in get
    self.model._meta.object_name
doraemon.project.models.DoesNotExist: Project matching query does not exist.
Mon, 29 Oct 2018 17:09:53 simplelogger.py[line:28] ERROR Project matching query does not exist.
Traceback (most recent call last):
  File "/Users/ethan/Documents/OneDrive/coding.net/doraemon_nirvana_lte/doraemon/model_managers/project_model_manager.py", line 198, in get
    result=super(ProjectManager,self).get_queryset().get(id=projectid)
  File "/Library/Frameworks/Python.framework/Versions/3.5/lib/python3.5/site-packages/django/db/models/query.py", line 403, in get
    self.model._meta.object_name
doraemon.project.models.DoesNotExist: Project matching query does not exist.
Mon, 29 Oct 2018 17:09:53 simplelogger.py[line:28] ERROR Project matching query does not exist.
Traceback (most recent call last):
  File "/Users/ethan/Documents/OneDrive/coding.net/doraemon_nirvana_lte/doraemon/model_managers/project_model_manager.py", line 198, in get
    result=super(ProjectManager,self).get_queryset().get(id=projectid)
  File "/Library/Frameworks/Python.framework/Versions/3.5/lib/python3.5/site-packages/django/db/models/query.py", line 403, in get
    self.model._meta.object_name
doraemon.project.models.DoesNotExist: Project matching query does not exist.
Mon, 29 Oct 2018 17:09:53 simplelogger.py[line:28] ERROR Project matching query does not exist.
Traceback (most recent call last):
  File "/Users/ethan/Documents/OneDrive/coding.net/doraemon_nirvana_lte/doraemon/model_managers/project_model_manager.py", line 198, in get
    result=super(ProjectManager,self).get_queryset().get(id=projectid)
  File "/Library/Frameworks/Python.framework/Versions/3.5/lib/python3.5/site-packages/django/db/models/query.py", line 403, in get
    self.model._meta.object_name
doraemon.project.models.DoesNotExist: Project matching query does not exist.
Mon, 29 Oct 2018 17:09:53 simplelogger.py[line:28] ERROR Project matching query does not exist.
Traceback (most recent call last):
  File "/Users/ethan/Documents/OneDrive/coding.net/doraemon_nirvana_lte/doraemon/model_managers/project_model_manager.py", line 198, in get
    result=super(ProjectManager,self).get_queryset().get(id=projectid)
  File "/Library/Frameworks/Python.framework/Versions/3.5/lib/python3.5/site-packages/django/db/models/query.py", line 403, in get
    self.model._meta.object_name
doraemon.project.models.DoesNotExist: Project matching query does not exist.
Mon, 29 Oct 2018 17:09:53 simplelogger.py[line:28] ERROR Project matching query does not exist.
Traceback (most recent call last):
  File "/Users/ethan/Documents/OneDrive/coding.net/doraemon_nirvana_lte/doraemon/model_managers/project_model_manager.py", line 198, in get
    result=super(ProjectManager,self).get_queryset().get(id=projectid)
  File "/Library/Frameworks/Python.framework/Versions/3.5/lib/python3.5/site-packages/django/db/models/query.py", line 403, in get
    self.model._meta.object_name
doraemon.project.models.DoesNotExist: Project matching query does not exist.
Mon, 29 Oct 2018 17:09:53 simplelogger.py[line:28] ERROR Project matching query does not exist.
Traceback (most recent call last):
  File "/Users/ethan/Documents/OneDrive/coding.net/doraemon_nirvana_lte/doraemon/model_managers/project_model_manager.py", line 198, in get
    result=super(ProjectManager,self).get_queryset().get(id=projectid)
  File "/Library/Frameworks/Python.framework/Versions/3.5/lib/python3.5/site-packages/django/db/models/query.py", line 403, in get
    self.model._meta.object_name
doraemon.project.models.DoesNotExist: Project matching query does not exist.
Mon, 29 Oct 2018 17:09:53 simplelogger.py[line:28] ERROR Project matching query does not exist.
Traceback (most recent call last):
  File "/Users/ethan/Documents/OneDrive/coding.net/doraemon_nirvana_lte/doraemon/model_managers/project_model_manager.py", line 198, in get
    result=super(ProjectManager,self).get_queryset().get(id=projectid)
  File "/Library/Frameworks/Python.framework/Versions/3.5/lib/python3.5/site-packages/django/db/models/query.py", line 403, in get
    self.model._meta.object_name
doraemon.project.models.DoesNotExist: Project matching query does not exist.
Mon, 29 Oct 2018 17:20:28 simplelogger.py[line:28] ERROR Project matching query does not exist.
Traceback (most recent call last):
  File "/Users/ethan/Documents/OneDrive/coding.net/doraemon_nirvana_lte/doraemon/model_managers/project_model_manager.py", line 198, in get
    result=super(ProjectManager,self).get_queryset().get(id=projectid)
  File "/Library/Frameworks/Python.framework/Versions/3.5/lib/python3.5/site-packages/django/db/models/query.py", line 403, in get
    self.model._meta.object_name
doraemon.project.models.DoesNotExist: Project matching query does not exist.
Mon, 29 Oct 2018 17:20:29 simplelogger.py[line:28] ERROR Project matching query does not exist.
Traceback (most recent call last):
  File "/Users/ethan/Documents/OneDrive/coding.net/doraemon_nirvana_lte/doraemon/model_managers/project_model_manager.py", line 198, in get
    result=super(ProjectManager,self).get_queryset().get(id=projectid)
  File "/Library/Frameworks/Python.framework/Versions/3.5/lib/python3.5/site-packages/django/db/models/query.py", line 403, in get
    self.model._meta.object_name
doraemon.project.models.DoesNotExist: Project matching query does not exist.
Mon, 29 Oct 2018 17:20:29 simplelogger.py[line:28] ERROR Project matching query does not exist.
Traceback (most recent call last):
  File "/Users/ethan/Documents/OneDrive/coding.net/doraemon_nirvana_lte/doraemon/model_managers/project_model_manager.py", line 198, in get
    result=super(ProjectManager,self).get_queryset().get(id=projectid)
  File "/Library/Frameworks/Python.framework/Versions/3.5/lib/python3.5/site-packages/django/db/models/query.py", line 403, in get
    self.model._meta.object_name
doraemon.project.models.DoesNotExist: Project matching query does not exist.
Mon, 29 Oct 2018 17:20:29 simplelogger.py[line:28] ERROR Project matching query does not exist.
Traceback (most recent call last):
  File "/Users/ethan/Documents/OneDrive/coding.net/doraemon_nirvana_lte/doraemon/model_managers/project_model_manager.py", line 198, in get
    result=super(ProjectManager,self).get_queryset().get(id=projectid)
  File "/Library/Frameworks/Python.framework/Versions/3.5/lib/python3.5/site-packages/django/db/models/query.py", line 403, in get
    self.model._meta.object_name
doraemon.project.models.DoesNotExist: Project matching query does not exist.
Mon, 29 Oct 2018 17:20:29 simplelogger.py[line:28] ERROR Project matching query does not exist.
Traceback (most recent call last):
  File "/Users/ethan/Documents/OneDrive/coding.net/doraemon_nirvana_lte/doraemon/model_managers/project_model_manager.py", line 198, in get
    result=super(ProjectManager,self).get_queryset().get(id=projectid)
  File "/Library/Frameworks/Python.framework/Versions/3.5/lib/python3.5/site-packages/django/db/models/query.py", line 403, in get
    self.model._meta.object_name
doraemon.project.models.DoesNotExist: Project matching query does not exist.
Mon, 29 Oct 2018 17:20:29 simplelogger.py[line:28] ERROR Project matching query does not exist.
Traceback (most recent call last):
  File "/Users/ethan/Documents/OneDrive/coding.net/doraemon_nirvana_lte/doraemon/model_managers/project_model_manager.py", line 198, in get
    result=super(ProjectManager,self).get_queryset().get(id=projectid)
  File "/Library/Frameworks/Python.framework/Versions/3.5/lib/python3.5/site-packages/django/db/models/query.py", line 403, in get
    self.model._meta.object_name
doraemon.project.models.DoesNotExist: Project matching query does not exist.
Mon, 29 Oct 2018 17:20:29 simplelogger.py[line:28] ERROR Project matching query does not exist.
Traceback (most recent call last):
  File "/Users/ethan/Documents/OneDrive/coding.net/doraemon_nirvana_lte/doraemon/model_managers/project_model_manager.py", line 198, in get
    result=super(ProjectManager,self).get_queryset().get(id=projectid)
  File "/Library/Frameworks/Python.framework/Versions/3.5/lib/python3.5/site-packages/django/db/models/query.py", line 403, in get
    self.model._meta.object_name
doraemon.project.models.DoesNotExist: Project matching query does not exist.
Mon, 29 Oct 2018 17:20:29 simplelogger.py[line:28] ERROR Project matching query does not exist.
Traceback (most recent call last):
  File "/Users/ethan/Documents/OneDrive/coding.net/doraemon_nirvana_lte/doraemon/model_managers/project_model_manager.py", line 198, in get
    result=super(ProjectManager,self).get_queryset().get(id=projectid)
  File "/Library/Frameworks/Python.framework/Versions/3.5/lib/python3.5/site-packages/django/db/models/query.py", line 403, in get
    self.model._meta.object_name
doraemon.project.models.DoesNotExist: Project matching query does not exist.
Mon, 29 Oct 2018 17:20:29 simplelogger.py[line:28] ERROR Project matching query does not exist.
Traceback (most recent call last):
  File "/Users/ethan/Documents/OneDrive/coding.net/doraemon_nirvana_lte/doraemon/model_managers/project_model_manager.py", line 198, in get
    result=super(ProjectManager,self).get_queryset().get(id=projectid)
  File "/Library/Frameworks/Python.framework/Versions/3.5/lib/python3.5/site-packages/django/db/models/query.py", line 403, in get
    self.model._meta.object_name
doraemon.project.models.DoesNotExist: Project matching query does not exist.
Mon, 29 Oct 2018 17:20:29 simplelogger.py[line:28] ERROR Project matching query does not exist.
Traceback (most recent call last):
  File "/Users/ethan/Documents/OneDrive/coding.net/doraemon_nirvana_lte/doraemon/model_managers/project_model_manager.py", line 198, in get
    result=super(ProjectManager,self).get_queryset().get(id=projectid)
  File "/Library/Frameworks/Python.framework/Versions/3.5/lib/python3.5/site-packages/django/db/models/query.py", line 403, in get
    self.model._meta.object_name
doraemon.project.models.DoesNotExist: Project matching query does not exist.
Mon, 29 Oct 2018 17:20:29 simplelogger.py[line:28] ERROR Project matching query does not exist.
Traceback (most recent call last):
  File "/Users/ethan/Documents/OneDrive/coding.net/doraemon_nirvana_lte/doraemon/model_managers/project_model_manager.py", line 198, in get
    result=super(ProjectManager,self).get_queryset().get(id=projectid)
  File "/Library/Frameworks/Python.framework/Versions/3.5/lib/python3.5/site-packages/django/db/models/query.py", line 403, in get
    self.model._meta.object_name
doraemon.project.models.DoesNotExist: Project matching query does not exist.
Tue, 30 Oct 2018 09:35:25 simplelogger.py[line:28] ERROR Project matching query does not exist.
Traceback (most recent call last):
  File "/Users/ethan/Documents/OneDrive/coding.net/doraemon_nirvana_lte/doraemon/model_managers/project_model_manager.py", line 198, in get
    result=super(ProjectManager,self).get_queryset().get(id=projectid)
  File "/Library/Frameworks/Python.framework/Versions/3.5/lib/python3.5/site-packages/django/db/models/query.py", line 403, in get
    self.model._meta.object_name
doraemon.project.models.DoesNotExist: Project matching query does not exist.
Tue, 30 Oct 2018 09:35:25 simplelogger.py[line:28] ERROR Project matching query does not exist.
Traceback (most recent call last):
  File "/Users/ethan/Documents/OneDrive/coding.net/doraemon_nirvana_lte/doraemon/model_managers/project_model_manager.py", line 198, in get
    result=super(ProjectManager,self).get_queryset().get(id=projectid)
  File "/Library/Frameworks/Python.framework/Versions/3.5/lib/python3.5/site-packages/django/db/models/query.py", line 403, in get
    self.model._meta.object_name
doraemon.project.models.DoesNotExist: Project matching query does not exist.
Tue, 30 Oct 2018 09:35:25 simplelogger.py[line:28] ERROR Project matching query does not exist.
Traceback (most recent call last):
  File "/Users/ethan/Documents/OneDrive/coding.net/doraemon_nirvana_lte/doraemon/model_managers/project_model_manager.py", line 198, in get
    result=super(ProjectManager,self).get_queryset().get(id=projectid)
  File "/Library/Frameworks/Python.framework/Versions/3.5/lib/python3.5/site-packages/django/db/models/query.py", line 403, in get
    self.model._meta.object_name
doraemon.project.models.DoesNotExist: Project matching query does not exist.
Tue, 30 Oct 2018 09:35:25 simplelogger.py[line:28] ERROR Project matching query does not exist.
Traceback (most recent call last):
  File "/Users/ethan/Documents/OneDrive/coding.net/doraemon_nirvana_lte/doraemon/model_managers/project_model_manager.py", line 198, in get
    result=super(ProjectManager,self).get_queryset().get(id=projectid)
  File "/Library/Frameworks/Python.framework/Versions/3.5/lib/python3.5/site-packages/django/db/models/query.py", line 403, in get
    self.model._meta.object_name
doraemon.project.models.DoesNotExist: Project matching query does not exist.
Tue, 30 Oct 2018 09:35:25 simplelogger.py[line:28] ERROR Project matching query does not exist.
Traceback (most recent call last):
  File "/Users/ethan/Documents/OneDrive/coding.net/doraemon_nirvana_lte/doraemon/model_managers/project_model_manager.py", line 198, in get
    result=super(ProjectManager,self).get_queryset().get(id=projectid)
  File "/Library/Frameworks/Python.framework/Versions/3.5/lib/python3.5/site-packages/django/db/models/query.py", line 403, in get
    self.model._meta.object_name
doraemon.project.models.DoesNotExist: Project matching query does not exist.
Tue, 30 Oct 2018 09:35:25 simplelogger.py[line:28] ERROR Project matching query does not exist.
Traceback (most recent call last):
  File "/Users/ethan/Documents/OneDrive/coding.net/doraemon_nirvana_lte/doraemon/model_managers/project_model_manager.py", line 198, in get
    result=super(ProjectManager,self).get_queryset().get(id=projectid)
  File "/Library/Frameworks/Python.framework/Versions/3.5/lib/python3.5/site-packages/django/db/models/query.py", line 403, in get
    self.model._meta.object_name
doraemon.project.models.DoesNotExist: Project matching query does not exist.
Tue, 30 Oct 2018 09:35:25 simplelogger.py[line:28] ERROR Project matching query does not exist.
Traceback (most recent call last):
  File "/Users/ethan/Documents/OneDrive/coding.net/doraemon_nirvana_lte/doraemon/model_managers/project_model_manager.py", line 198, in get
    result=super(ProjectManager,self).get_queryset().get(id=projectid)
  File "/Library/Frameworks/Python.framework/Versions/3.5/lib/python3.5/site-packages/django/db/models/query.py", line 403, in get
    self.model._meta.object_name
doraemon.project.models.DoesNotExist: Project matching query does not exist.
Tue, 30 Oct 2018 09:35:25 simplelogger.py[line:28] ERROR Project matching query does not exist.
Traceback (most recent call last):
  File "/Users/ethan/Documents/OneDrive/coding.net/doraemon_nirvana_lte/doraemon/model_managers/project_model_manager.py", line 198, in get
    result=super(ProjectManager,self).get_queryset().get(id=projectid)
  File "/Library/Frameworks/Python.framework/Versions/3.5/lib/python3.5/site-packages/django/db/models/query.py", line 403, in get
    self.model._meta.object_name
doraemon.project.models.DoesNotExist: Project matching query does not exist.
Tue, 30 Oct 2018 09:35:25 simplelogger.py[line:28] ERROR Project matching query does not exist.
Traceback (most recent call last):
  File "/Users/ethan/Documents/OneDrive/coding.net/doraemon_nirvana_lte/doraemon/model_managers/project_model_manager.py", line 198, in get
    result=super(ProjectManager,self).get_queryset().get(id=projectid)
  File "/Library/Frameworks/Python.framework/Versions/3.5/lib/python3.5/site-packages/django/db/models/query.py", line 403, in get
    self.model._meta.object_name
doraemon.project.models.DoesNotExist: Project matching query does not exist.
Tue, 30 Oct 2018 09:35:25 simplelogger.py[line:28] ERROR Project matching query does not exist.
Traceback (most recent call last):
  File "/Users/ethan/Documents/OneDrive/coding.net/doraemon_nirvana_lte/doraemon/model_managers/project_model_manager.py", line 198, in get
    result=super(ProjectManager,self).get_queryset().get(id=projectid)
  File "/Library/Frameworks/Python.framework/Versions/3.5/lib/python3.5/site-packages/django/db/models/query.py", line 403, in get
    self.model._meta.object_name
doraemon.project.models.DoesNotExist: Project matching query does not exist.
Tue, 30 Oct 2018 09:35:25 simplelogger.py[line:28] ERROR Project matching query does not exist.
Traceback (most recent call last):
  File "/Users/ethan/Documents/OneDrive/coding.net/doraemon_nirvana_lte/doraemon/model_managers/project_model_manager.py", line 198, in get
    result=super(ProjectManager,self).get_queryset().get(id=projectid)
  File "/Library/Frameworks/Python.framework/Versions/3.5/lib/python3.5/site-packages/django/db/models/query.py", line 403, in get
    self.model._meta.object_name
doraemon.project.models.DoesNotExist: Project matching query does not exist.
Tue, 30 Oct 2018 09:35:57 simplelogger.py[line:28] ERROR 10.69.59.119:8807: [Errno 61] Connection refused
Traceback (most recent call last):
  File "/Users/ethan/Documents/OneDrive/coding.net/doraemon_nirvana_lte/doraemon/gatesidelib/mongodb_helper.py", line 84, in get_file_bucket
    grid_out =bucket_files.open_download_stream(ObjectId(file_id))
  File "/Library/Frameworks/Python.framework/Versions/3.5/lib/python3.5/site-packages/gridfs/__init__.py", line 598, in open_download_stream
    gout._ensure_file()
  File "/Library/Frameworks/Python.framework/Versions/3.5/lib/python3.5/site-packages/gridfs/grid_file.py", line 432, in _ensure_file
    self._file = self.__files.find_one({"_id": self.__file_id})
  File "/Library/Frameworks/Python.framework/Versions/3.5/lib/python3.5/site-packages/pymongo/collection.py", line 1102, in find_one
    for result in cursor.limit(-1):
  File "/Library/Frameworks/Python.framework/Versions/3.5/lib/python3.5/site-packages/pymongo/cursor.py", line 1114, in next
    if len(self.__data) or self._refresh():
  File "/Library/Frameworks/Python.framework/Versions/3.5/lib/python3.5/site-packages/pymongo/cursor.py", line 1036, in _refresh
    self.__collation))
  File "/Library/Frameworks/Python.framework/Versions/3.5/lib/python3.5/site-packages/pymongo/cursor.py", line 873, in __send_message
    **kwargs)
  File "/Library/Frameworks/Python.framework/Versions/3.5/lib/python3.5/site-packages/pymongo/mongo_client.py", line 888, in _send_message_with_response
    server = topology.select_server(selector)
  File "/Library/Frameworks/Python.framework/Versions/3.5/lib/python3.5/site-packages/pymongo/topology.py", line 214, in select_server
    address))
  File "/Library/Frameworks/Python.framework/Versions/3.5/lib/python3.5/site-packages/pymongo/topology.py", line 189, in select_servers
    self._error_message(selector))
pymongo.errors.ServerSelectionTimeoutError: 10.69.59.119:8807: [Errno 61] Connection refused
Tue, 30 Oct 2018 09:36:27 simplelogger.py[line:28] ERROR 10.69.59.119:8807: [Errno 61] Connection refused
Traceback (most recent call last):
  File "/Users/ethan/Documents/OneDrive/coding.net/doraemon_nirvana_lte/doraemon/gatesidelib/mongodb_helper.py", line 84, in get_file_bucket
    grid_out =bucket_files.open_download_stream(ObjectId(file_id))
  File "/Library/Frameworks/Python.framework/Versions/3.5/lib/python3.5/site-packages/gridfs/__init__.py", line 598, in open_download_stream
    gout._ensure_file()
  File "/Library/Frameworks/Python.framework/Versions/3.5/lib/python3.5/site-packages/gridfs/grid_file.py", line 432, in _ensure_file
    self._file = self.__files.find_one({"_id": self.__file_id})
  File "/Library/Frameworks/Python.framework/Versions/3.5/lib/python3.5/site-packages/pymongo/collection.py", line 1102, in find_one
    for result in cursor.limit(-1):
  File "/Library/Frameworks/Python.framework/Versions/3.5/lib/python3.5/site-packages/pymongo/cursor.py", line 1114, in next
    if len(self.__data) or self._refresh():
  File "/Library/Frameworks/Python.framework/Versions/3.5/lib/python3.5/site-packages/pymongo/cursor.py", line 1036, in _refresh
    self.__collation))
  File "/Library/Frameworks/Python.framework/Versions/3.5/lib/python3.5/site-packages/pymongo/cursor.py", line 873, in __send_message
    **kwargs)
  File "/Library/Frameworks/Python.framework/Versions/3.5/lib/python3.5/site-packages/pymongo/mongo_client.py", line 888, in _send_message_with_response
    server = topology.select_server(selector)
  File "/Library/Frameworks/Python.framework/Versions/3.5/lib/python3.5/site-packages/pymongo/topology.py", line 214, in select_server
    address))
  File "/Library/Frameworks/Python.framework/Versions/3.5/lib/python3.5/site-packages/pymongo/topology.py", line 189, in select_servers
    self._error_message(selector))
pymongo.errors.ServerSelectionTimeoutError: 10.69.59.119:8807: [Errno 61] Connection refused
Tue, 30 Oct 2018 12:54:40 simplelogger.py[line:28] ERROR 'AnonymousUser' object has no attribute 'extend_info'
Traceback (most recent call last):
  File "/Users/ethan/Documents/OneDrive/coding.net/doraemon_nirvana_lte/doraemon/business/ucenter/account_service.py", line 35, in get_avatar_url
    if user.extend_info:
AttributeError: 'AnonymousUser' object has no attribute 'extend_info'
Tue, 30 Oct 2018 12:54:42 simplelogger.py[line:28] ERROR 'AnonymousUser' object has no attribute 'extend_info'
Traceback (most recent call last):
  File "/Users/ethan/Documents/OneDrive/coding.net/doraemon_nirvana_lte/doraemon/business/ucenter/account_service.py", line 35, in get_avatar_url
    if user.extend_info:
AttributeError: 'AnonymousUser' object has no attribute 'extend_info'
Tue, 30 Oct 2018 12:54:42 simplelogger.py[line:28] ERROR 'AnonymousUser' object has no attribute 'extend_info'
Traceback (most recent call last):
  File "/Users/ethan/Documents/OneDrive/coding.net/doraemon_nirvana_lte/doraemon/business/ucenter/account_service.py", line 35, in get_avatar_url
    if user.extend_info:
AttributeError: 'AnonymousUser' object has no attribute 'extend_info'
Tue, 30 Oct 2018 12:54:42 simplelogger.py[line:28] ERROR 'AnonymousUser' object has no attribute 'extend_info'
Traceback (most recent call last):
  File "/Users/ethan/Documents/OneDrive/coding.net/doraemon_nirvana_lte/doraemon/business/ucenter/account_service.py", line 35, in get_avatar_url
    if user.extend_info:
AttributeError: 'AnonymousUser' object has no attribute 'extend_info'
Tue, 30 Oct 2018 12:54:43 simplelogger.py[line:28] ERROR 'AnonymousUser' object has no attribute 'extend_info'
Traceback (most recent call last):
  File "/Users/ethan/Documents/OneDrive/coding.net/doraemon_nirvana_lte/doraemon/business/ucenter/account_service.py", line 35, in get_avatar_url
    if user.extend_info:
AttributeError: 'AnonymousUser' object has no attribute 'extend_info'
Tue, 30 Oct 2018 12:54:43 simplelogger.py[line:28] ERROR 'AnonymousUser' object has no attribute 'extend_info'
Traceback (most recent call last):
  File "/Users/ethan/Documents/OneDrive/coding.net/doraemon_nirvana_lte/doraemon/business/ucenter/account_service.py", line 35, in get_avatar_url
    if user.extend_info:
AttributeError: 'AnonymousUser' object has no attribute 'extend_info'
Tue, 30 Oct 2018 12:54:44 simplelogger.py[line:28] ERROR 'AnonymousUser' object has no attribute 'extend_info'
Traceback (most recent call last):
  File "/Users/ethan/Documents/OneDrive/coding.net/doraemon_nirvana_lte/doraemon/business/ucenter/account_service.py", line 35, in get_avatar_url
    if user.extend_info:
AttributeError: 'AnonymousUser' object has no attribute 'extend_info'
Tue, 30 Oct 2018 12:54:44 simplelogger.py[line:28] ERROR 'AnonymousUser' object has no attribute 'extend_info'
Traceback (most recent call last):
  File "/Users/ethan/Documents/OneDrive/coding.net/doraemon_nirvana_lte/doraemon/business/ucenter/account_service.py", line 35, in get_avatar_url
    if user.extend_info:
AttributeError: 'AnonymousUser' object has no attribute 'extend_info'
Tue, 30 Oct 2018 12:54:45 simplelogger.py[line:28] ERROR 'AnonymousUser' object has no attribute 'extend_info'
Traceback (most recent call last):
  File "/Users/ethan/Documents/OneDrive/coding.net/doraemon_nirvana_lte/doraemon/business/ucenter/account_service.py", line 35, in get_avatar_url
    if user.extend_info:
AttributeError: 'AnonymousUser' object has no attribute 'extend_info'
Tue, 30 Oct 2018 12:54:45 simplelogger.py[line:28] ERROR 'AnonymousUser' object has no attribute 'extend_info'
Traceback (most recent call last):
  File "/Users/ethan/Documents/OneDrive/coding.net/doraemon_nirvana_lte/doraemon/business/ucenter/account_service.py", line 35, in get_avatar_url
    if user.extend_info:
AttributeError: 'AnonymousUser' object has no attribute 'extend_info'
Tue, 30 Oct 2018 12:54:45 simplelogger.py[line:28] ERROR 'AnonymousUser' object has no attribute 'extend_info'
Traceback (most recent call last):
  File "/Users/ethan/Documents/OneDrive/coding.net/doraemon_nirvana_lte/doraemon/business/ucenter/account_service.py", line 35, in get_avatar_url
    if user.extend_info:
AttributeError: 'AnonymousUser' object has no attribute 'extend_info'
Tue, 30 Oct 2018 12:54:46 simplelogger.py[line:28] ERROR 'AnonymousUser' object has no attribute 'extend_info'
Traceback (most recent call last):
  File "/Users/ethan/Documents/OneDrive/coding.net/doraemon_nirvana_lte/doraemon/business/ucenter/account_service.py", line 35, in get_avatar_url
    if user.extend_info:
AttributeError: 'AnonymousUser' object has no attribute 'extend_info'
Tue, 30 Oct 2018 12:54:46 simplelogger.py[line:28] ERROR 'AnonymousUser' object has no attribute 'extend_info'
Traceback (most recent call last):
  File "/Users/ethan/Documents/OneDrive/coding.net/doraemon_nirvana_lte/doraemon/business/ucenter/account_service.py", line 35, in get_avatar_url
    if user.extend_info:
AttributeError: 'AnonymousUser' object has no attribute 'extend_info'
Tue, 30 Oct 2018 12:55:03 simplelogger.py[line:28] ERROR Project matching query does not exist.
Traceback (most recent call last):
  File "/Users/ethan/Documents/OneDrive/coding.net/doraemon_nirvana_lte/doraemon/model_managers/project_model_manager.py", line 198, in get
    result=super(ProjectManager,self).get_queryset().get(id=projectid)
  File "/Library/Frameworks/Python.framework/Versions/3.5/lib/python3.5/site-packages/django/db/models/query.py", line 403, in get
    self.model._meta.object_name
doraemon.project.models.DoesNotExist: Project matching query does not exist.
Tue, 30 Oct 2018 12:55:03 simplelogger.py[line:28] ERROR Project matching query does not exist.
Traceback (most recent call last):
  File "/Users/ethan/Documents/OneDrive/coding.net/doraemon_nirvana_lte/doraemon/model_managers/project_model_manager.py", line 198, in get
    result=super(ProjectManager,self).get_queryset().get(id=projectid)
  File "/Library/Frameworks/Python.framework/Versions/3.5/lib/python3.5/site-packages/django/db/models/query.py", line 403, in get
    self.model._meta.object_name
doraemon.project.models.DoesNotExist: Project matching query does not exist.
Tue, 30 Oct 2018 12:55:03 simplelogger.py[line:28] ERROR Project matching query does not exist.
Traceback (most recent call last):
  File "/Users/ethan/Documents/OneDrive/coding.net/doraemon_nirvana_lte/doraemon/model_managers/project_model_manager.py", line 198, in get
    result=super(ProjectManager,self).get_queryset().get(id=projectid)
  File "/Library/Frameworks/Python.framework/Versions/3.5/lib/python3.5/site-packages/django/db/models/query.py", line 403, in get
    self.model._meta.object_name
doraemon.project.models.DoesNotExist: Project matching query does not exist.
Tue, 30 Oct 2018 12:55:03 simplelogger.py[line:28] ERROR Project matching query does not exist.
Traceback (most recent call last):
  File "/Users/ethan/Documents/OneDrive/coding.net/doraemon_nirvana_lte/doraemon/model_managers/project_model_manager.py", line 198, in get
    result=super(ProjectManager,self).get_queryset().get(id=projectid)
  File "/Library/Frameworks/Python.framework/Versions/3.5/lib/python3.5/site-packages/django/db/models/query.py", line 403, in get
    self.model._meta.object_name
doraemon.project.models.DoesNotExist: Project matching query does not exist.
Tue, 30 Oct 2018 12:55:03 simplelogger.py[line:28] ERROR Project matching query does not exist.
Traceback (most recent call last):
  File "/Users/ethan/Documents/OneDrive/coding.net/doraemon_nirvana_lte/doraemon/model_managers/project_model_manager.py", line 198, in get
    result=super(ProjectManager,self).get_queryset().get(id=projectid)
  File "/Library/Frameworks/Python.framework/Versions/3.5/lib/python3.5/site-packages/django/db/models/query.py", line 403, in get
    self.model._meta.object_name
doraemon.project.models.DoesNotExist: Project matching query does not exist.
Tue, 30 Oct 2018 12:55:03 simplelogger.py[line:28] ERROR Project matching query does not exist.
Traceback (most recent call last):
  File "/Users/ethan/Documents/OneDrive/coding.net/doraemon_nirvana_lte/doraemon/model_managers/project_model_manager.py", line 198, in get
    result=super(ProjectManager,self).get_queryset().get(id=projectid)
  File "/Library/Frameworks/Python.framework/Versions/3.5/lib/python3.5/site-packages/django/db/models/query.py", line 403, in get
    self.model._meta.object_name
doraemon.project.models.DoesNotExist: Project matching query does not exist.
Tue, 30 Oct 2018 12:55:03 simplelogger.py[line:28] ERROR Project matching query does not exist.
Traceback (most recent call last):
  File "/Users/ethan/Documents/OneDrive/coding.net/doraemon_nirvana_lte/doraemon/model_managers/project_model_manager.py", line 198, in get
    result=super(ProjectManager,self).get_queryset().get(id=projectid)
  File "/Library/Frameworks/Python.framework/Versions/3.5/lib/python3.5/site-packages/django/db/models/query.py", line 403, in get
    self.model._meta.object_name
doraemon.project.models.DoesNotExist: Project matching query does not exist.
Tue, 30 Oct 2018 12:55:03 simplelogger.py[line:28] ERROR Project matching query does not exist.
Traceback (most recent call last):
  File "/Users/ethan/Documents/OneDrive/coding.net/doraemon_nirvana_lte/doraemon/model_managers/project_model_manager.py", line 198, in get
    result=super(ProjectManager,self).get_queryset().get(id=projectid)
  File "/Library/Frameworks/Python.framework/Versions/3.5/lib/python3.5/site-packages/django/db/models/query.py", line 403, in get
    self.model._meta.object_name
doraemon.project.models.DoesNotExist: Project matching query does not exist.
Tue, 30 Oct 2018 12:55:03 simplelogger.py[line:28] ERROR Project matching query does not exist.
Traceback (most recent call last):
  File "/Users/ethan/Documents/OneDrive/coding.net/doraemon_nirvana_lte/doraemon/model_managers/project_model_manager.py", line 198, in get
    result=super(ProjectManager,self).get_queryset().get(id=projectid)
  File "/Library/Frameworks/Python.framework/Versions/3.5/lib/python3.5/site-packages/django/db/models/query.py", line 403, in get
    self.model._meta.object_name
doraemon.project.models.DoesNotExist: Project matching query does not exist.
Tue, 30 Oct 2018 12:55:03 simplelogger.py[line:28] ERROR Project matching query does not exist.
Traceback (most recent call last):
  File "/Users/ethan/Documents/OneDrive/coding.net/doraemon_nirvana_lte/doraemon/model_managers/project_model_manager.py", line 198, in get
    result=super(ProjectManager,self).get_queryset().get(id=projectid)
  File "/Library/Frameworks/Python.framework/Versions/3.5/lib/python3.5/site-packages/django/db/models/query.py", line 403, in get
    self.model._meta.object_name
doraemon.project.models.DoesNotExist: Project matching query does not exist.
Tue, 30 Oct 2018 12:55:03 simplelogger.py[line:28] ERROR Project matching query does not exist.
Traceback (most recent call last):
  File "/Users/ethan/Documents/OneDrive/coding.net/doraemon_nirvana_lte/doraemon/model_managers/project_model_manager.py", line 198, in get
    result=super(ProjectManager,self).get_queryset().get(id=projectid)
  File "/Library/Frameworks/Python.framework/Versions/3.5/lib/python3.5/site-packages/django/db/models/query.py", line 403, in get
    self.model._meta.object_name
doraemon.project.models.DoesNotExist: Project matching query does not exist.
Tue, 30 Oct 2018 12:55:18 simplelogger.py[line:28] ERROR Project matching query does not exist.
Traceback (most recent call last):
  File "/Users/ethan/Documents/OneDrive/coding.net/doraemon_nirvana_lte/doraemon/model_managers/project_model_manager.py", line 198, in get
    result=super(ProjectManager,self).get_queryset().get(id=projectid)
  File "/Library/Frameworks/Python.framework/Versions/3.5/lib/python3.5/site-packages/django/db/models/query.py", line 403, in get
    self.model._meta.object_name
doraemon.project.models.DoesNotExist: Project matching query does not exist.
Tue, 30 Oct 2018 12:55:18 simplelogger.py[line:28] ERROR Project matching query does not exist.
Traceback (most recent call last):
  File "/Users/ethan/Documents/OneDrive/coding.net/doraemon_nirvana_lte/doraemon/model_managers/project_model_manager.py", line 198, in get
    result=super(ProjectManager,self).get_queryset().get(id=projectid)
  File "/Library/Frameworks/Python.framework/Versions/3.5/lib/python3.5/site-packages/django/db/models/query.py", line 403, in get
    self.model._meta.object_name
doraemon.project.models.DoesNotExist: Project matching query does not exist.
Tue, 30 Oct 2018 12:55:18 simplelogger.py[line:28] ERROR Project matching query does not exist.
Traceback (most recent call last):
  File "/Users/ethan/Documents/OneDrive/coding.net/doraemon_nirvana_lte/doraemon/model_managers/project_model_manager.py", line 198, in get
    result=super(ProjectManager,self).get_queryset().get(id=projectid)
  File "/Library/Frameworks/Python.framework/Versions/3.5/lib/python3.5/site-packages/django/db/models/query.py", line 403, in get
    self.model._meta.object_name
doraemon.project.models.DoesNotExist: Project matching query does not exist.
Tue, 30 Oct 2018 12:55:18 simplelogger.py[line:28] ERROR Project matching query does not exist.
Traceback (most recent call last):
  File "/Users/ethan/Documents/OneDrive/coding.net/doraemon_nirvana_lte/doraemon/model_managers/project_model_manager.py", line 198, in get
    result=super(ProjectManager,self).get_queryset().get(id=projectid)
  File "/Library/Frameworks/Python.framework/Versions/3.5/lib/python3.5/site-packages/django/db/models/query.py", line 403, in get
    self.model._meta.object_name
doraemon.project.models.DoesNotExist: Project matching query does not exist.
Tue, 30 Oct 2018 12:55:18 simplelogger.py[line:28] ERROR Project matching query does not exist.
Traceback (most recent call last):
  File "/Users/ethan/Documents/OneDrive/coding.net/doraemon_nirvana_lte/doraemon/model_managers/project_model_manager.py", line 198, in get
    result=super(ProjectManager,self).get_queryset().get(id=projectid)
  File "/Library/Frameworks/Python.framework/Versions/3.5/lib/python3.5/site-packages/django/db/models/query.py", line 403, in get
    self.model._meta.object_name
doraemon.project.models.DoesNotExist: Project matching query does not exist.
Tue, 30 Oct 2018 12:55:18 simplelogger.py[line:28] ERROR Project matching query does not exist.
Traceback (most recent call last):
  File "/Users/ethan/Documents/OneDrive/coding.net/doraemon_nirvana_lte/doraemon/model_managers/project_model_manager.py", line 198, in get
    result=super(ProjectManager,self).get_queryset().get(id=projectid)
  File "/Library/Frameworks/Python.framework/Versions/3.5/lib/python3.5/site-packages/django/db/models/query.py", line 403, in get
    self.model._meta.object_name
doraemon.project.models.DoesNotExist: Project matching query does not exist.
Tue, 30 Oct 2018 12:55:18 simplelogger.py[line:28] ERROR Project matching query does not exist.
Traceback (most recent call last):
  File "/Users/ethan/Documents/OneDrive/coding.net/doraemon_nirvana_lte/doraemon/model_managers/project_model_manager.py", line 198, in get
    result=super(ProjectManager,self).get_queryset().get(id=projectid)
  File "/Library/Frameworks/Python.framework/Versions/3.5/lib/python3.5/site-packages/django/db/models/query.py", line 403, in get
    self.model._meta.object_name
doraemon.project.models.DoesNotExist: Project matching query does not exist.
Tue, 30 Oct 2018 12:55:18 simplelogger.py[line:28] ERROR Project matching query does not exist.
Traceback (most recent call last):
  File "/Users/ethan/Documents/OneDrive/coding.net/doraemon_nirvana_lte/doraemon/model_managers/project_model_manager.py", line 198, in get
    result=super(ProjectManager,self).get_queryset().get(id=projectid)
  File "/Library/Frameworks/Python.framework/Versions/3.5/lib/python3.5/site-packages/django/db/models/query.py", line 403, in get
    self.model._meta.object_name
doraemon.project.models.DoesNotExist: Project matching query does not exist.
Tue, 30 Oct 2018 12:55:18 simplelogger.py[line:28] ERROR Project matching query does not exist.
Traceback (most recent call last):
  File "/Users/ethan/Documents/OneDrive/coding.net/doraemon_nirvana_lte/doraemon/model_managers/project_model_manager.py", line 198, in get
    result=super(ProjectManager,self).get_queryset().get(id=projectid)
  File "/Library/Frameworks/Python.framework/Versions/3.5/lib/python3.5/site-packages/django/db/models/query.py", line 403, in get
    self.model._meta.object_name
doraemon.project.models.DoesNotExist: Project matching query does not exist.
Tue, 30 Oct 2018 12:55:18 simplelogger.py[line:28] ERROR Project matching query does not exist.
Traceback (most recent call last):
  File "/Users/ethan/Documents/OneDrive/coding.net/doraemon_nirvana_lte/doraemon/model_managers/project_model_manager.py", line 198, in get
    result=super(ProjectManager,self).get_queryset().get(id=projectid)
  File "/Library/Frameworks/Python.framework/Versions/3.5/lib/python3.5/site-packages/django/db/models/query.py", line 403, in get
    self.model._meta.object_name
doraemon.project.models.DoesNotExist: Project matching query does not exist.
Tue, 30 Oct 2018 12:55:18 simplelogger.py[line:28] ERROR Project matching query does not exist.
Traceback (most recent call last):
  File "/Users/ethan/Documents/OneDrive/coding.net/doraemon_nirvana_lte/doraemon/model_managers/project_model_manager.py", line 198, in get
    result=super(ProjectManager,self).get_queryset().get(id=projectid)
  File "/Library/Frameworks/Python.framework/Versions/3.5/lib/python3.5/site-packages/django/db/models/query.py", line 403, in get
    self.model._meta.object_name
doraemon.project.models.DoesNotExist: Project matching query does not exist.
Tue, 30 Oct 2018 13:40:44 simplelogger.py[line:28] ERROR User matching query does not exist.
Traceback (most recent call last):
  File "/Users/ethan/Documents/OneDrive/coding.net/doraemon_nirvana_lte/doraemon/business/ci/ci_task_queue_service.py", line 39, in start_user
    started_by = User.objects.get(id=ci_task_history.StartedBy)
  File "/Library/Frameworks/Python.framework/Versions/3.5/lib/python3.5/site-packages/django/db/models/manager.py", line 82, in manager_method
    return getattr(self.get_queryset(), name)(*args, **kwargs)
  File "/Library/Frameworks/Python.framework/Versions/3.5/lib/python3.5/site-packages/django/db/models/query.py", line 403, in get
    self.model._meta.object_name
django.contrib.auth.models.DoesNotExist: User matching query does not exist.
Tue, 30 Oct 2018 13:40:44 simplelogger.py[line:28] ERROR User matching query does not exist.
Traceback (most recent call last):
  File "/Users/ethan/Documents/OneDrive/coding.net/doraemon_nirvana_lte/doraemon/business/ci/ci_task_queue_service.py", line 39, in start_user
    started_by = User.objects.get(id=ci_task_history.StartedBy)
  File "/Library/Frameworks/Python.framework/Versions/3.5/lib/python3.5/site-packages/django/db/models/manager.py", line 82, in manager_method
    return getattr(self.get_queryset(), name)(*args, **kwargs)
  File "/Library/Frameworks/Python.framework/Versions/3.5/lib/python3.5/site-packages/django/db/models/query.py", line 403, in get
    self.model._meta.object_name
django.contrib.auth.models.DoesNotExist: User matching query does not exist.
Tue, 30 Oct 2018 13:41:32 simplelogger.py[line:28] ERROR list index out of range
Traceback (most recent call last):
  File "/Users/ethan/Documents/OneDrive/coding.net/doraemon_nirvana_lte/doraemon/business/ci/ci_task_queue_service.py", line 38, in start_user
    ci_task_history = CITaskHistory.objects.get_history_by_tq(tq_id)
  File "/Users/ethan/Documents/OneDrive/coding.net/doraemon_nirvana_lte/doraemon/model_managers/ci_model_manager.py", line 187, in get_history_by_tq
    return result[0]
  File "/Library/Frameworks/Python.framework/Versions/3.5/lib/python3.5/site-packages/django/db/models/query.py", line 307, in __getitem__
    return qs._result_cache[0]
IndexError: list index out of range
Tue, 30 Oct 2018 14:39:42 simplelogger.py[line:28] ERROR User matching query does not exist.
Traceback (most recent call last):
  File "/Users/ethan/Documents/OneDrive/coding.net/doraemon_nirvana_lte/doraemon/business/ci/ci_task_queue_service.py", line 39, in start_user
    started_by = User.objects.get(id=ci_task_history.StartedBy)
  File "/Library/Frameworks/Python.framework/Versions/3.5/lib/python3.5/site-packages/django/db/models/manager.py", line 82, in manager_method
    return getattr(self.get_queryset(), name)(*args, **kwargs)
  File "/Library/Frameworks/Python.framework/Versions/3.5/lib/python3.5/site-packages/django/db/models/query.py", line 403, in get
    self.model._meta.object_name
django.contrib.auth.models.DoesNotExist: User matching query does not exist.
Tue, 30 Oct 2018 14:39:43 simplelogger.py[line:28] ERROR User matching query does not exist.
Traceback (most recent call last):
  File "/Users/ethan/Documents/OneDrive/coding.net/doraemon_nirvana_lte/doraemon/business/ci/ci_task_queue_service.py", line 39, in start_user
    started_by = User.objects.get(id=ci_task_history.StartedBy)
  File "/Library/Frameworks/Python.framework/Versions/3.5/lib/python3.5/site-packages/django/db/models/manager.py", line 82, in manager_method
    return getattr(self.get_queryset(), name)(*args, **kwargs)
  File "/Library/Frameworks/Python.framework/Versions/3.5/lib/python3.5/site-packages/django/db/models/query.py", line 403, in get
    self.model._meta.object_name
django.contrib.auth.models.DoesNotExist: User matching query does not exist.
Tue, 30 Oct 2018 14:40:26 simplelogger.py[line:28] ERROR User matching query does not exist.
Traceback (most recent call last):
  File "/Users/ethan/Documents/OneDrive/coding.net/doraemon_nirvana_lte/doraemon/business/ci/ci_task_queue_service.py", line 39, in start_user
    started_by = User.objects.get(id=ci_task_history.StartedBy)
  File "/Library/Frameworks/Python.framework/Versions/3.5/lib/python3.5/site-packages/django/db/models/manager.py", line 82, in manager_method
    return getattr(self.get_queryset(), name)(*args, **kwargs)
  File "/Library/Frameworks/Python.framework/Versions/3.5/lib/python3.5/site-packages/django/db/models/query.py", line 403, in get
    self.model._meta.object_name
django.contrib.auth.models.DoesNotExist: User matching query does not exist.
Tue, 30 Oct 2018 14:40:26 simplelogger.py[line:28] ERROR User matching query does not exist.
Traceback (most recent call last):
  File "/Users/ethan/Documents/OneDrive/coding.net/doraemon_nirvana_lte/doraemon/business/ci/ci_task_queue_service.py", line 39, in start_user
    started_by = User.objects.get(id=ci_task_history.StartedBy)
  File "/Library/Frameworks/Python.framework/Versions/3.5/lib/python3.5/site-packages/django/db/models/manager.py", line 82, in manager_method
    return getattr(self.get_queryset(), name)(*args, **kwargs)
  File "/Library/Frameworks/Python.framework/Versions/3.5/lib/python3.5/site-packages/django/db/models/query.py", line 403, in get
    self.model._meta.object_name
django.contrib.auth.models.DoesNotExist: User matching query does not exist.
Tue, 30 Oct 2018 15:38:43 simplelogger.py[line:28] ERROR User matching query does not exist.
Traceback (most recent call last):
  File "/Users/ethan/Documents/OneDrive/coding.net/doraemon_nirvana_lte/doraemon/business/ci/ci_task_queue_service.py", line 39, in start_user
    started_by = User.objects.get(id=ci_task_history.StartedBy)
  File "/Library/Frameworks/Python.framework/Versions/3.5/lib/python3.5/site-packages/django/db/models/manager.py", line 82, in manager_method
    return getattr(self.get_queryset(), name)(*args, **kwargs)
  File "/Library/Frameworks/Python.framework/Versions/3.5/lib/python3.5/site-packages/django/db/models/query.py", line 403, in get
    self.model._meta.object_name
django.contrib.auth.models.DoesNotExist: User matching query does not exist.
Tue, 30 Oct 2018 15:38:43 simplelogger.py[line:28] ERROR User matching query does not exist.
Traceback (most recent call last):
  File "/Users/ethan/Documents/OneDrive/coding.net/doraemon_nirvana_lte/doraemon/business/ci/ci_task_queue_service.py", line 39, in start_user
    started_by = User.objects.get(id=ci_task_history.StartedBy)
  File "/Library/Frameworks/Python.framework/Versions/3.5/lib/python3.5/site-packages/django/db/models/manager.py", line 82, in manager_method
    return getattr(self.get_queryset(), name)(*args, **kwargs)
  File "/Library/Frameworks/Python.framework/Versions/3.5/lib/python3.5/site-packages/django/db/models/query.py", line 403, in get
    self.model._meta.object_name
django.contrib.auth.models.DoesNotExist: User matching query does not exist.
Tue, 30 Oct 2018 16:37:43 simplelogger.py[line:28] ERROR User matching query does not exist.
Traceback (most recent call last):
  File "/Users/ethan/Documents/OneDrive/coding.net/doraemon_nirvana_lte/doraemon/business/ci/ci_task_queue_service.py", line 39, in start_user
    started_by = User.objects.get(id=ci_task_history.StartedBy)
  File "/Library/Frameworks/Python.framework/Versions/3.5/lib/python3.5/site-packages/django/db/models/manager.py", line 82, in manager_method
    return getattr(self.get_queryset(), name)(*args, **kwargs)
  File "/Library/Frameworks/Python.framework/Versions/3.5/lib/python3.5/site-packages/django/db/models/query.py", line 403, in get
    self.model._meta.object_name
django.contrib.auth.models.DoesNotExist: User matching query does not exist.
Tue, 30 Oct 2018 16:37:43 simplelogger.py[line:28] ERROR User matching query does not exist.
Traceback (most recent call last):
  File "/Users/ethan/Documents/OneDrive/coding.net/doraemon_nirvana_lte/doraemon/business/ci/ci_task_queue_service.py", line 39, in start_user
    started_by = User.objects.get(id=ci_task_history.StartedBy)
  File "/Library/Frameworks/Python.framework/Versions/3.5/lib/python3.5/site-packages/django/db/models/manager.py", line 82, in manager_method
    return getattr(self.get_queryset(), name)(*args, **kwargs)
  File "/Library/Frameworks/Python.framework/Versions/3.5/lib/python3.5/site-packages/django/db/models/query.py", line 403, in get
    self.model._meta.object_name
django.contrib.auth.models.DoesNotExist: User matching query does not exist.
Tue, 30 Oct 2018 17:36:43 simplelogger.py[line:28] ERROR User matching query does not exist.
Traceback (most recent call last):
  File "/Users/ethan/Documents/OneDrive/coding.net/doraemon_nirvana_lte/doraemon/business/ci/ci_task_queue_service.py", line 39, in start_user
    started_by = User.objects.get(id=ci_task_history.StartedBy)
  File "/Library/Frameworks/Python.framework/Versions/3.5/lib/python3.5/site-packages/django/db/models/manager.py", line 82, in manager_method
    return getattr(self.get_queryset(), name)(*args, **kwargs)
  File "/Library/Frameworks/Python.framework/Versions/3.5/lib/python3.5/site-packages/django/db/models/query.py", line 403, in get
    self.model._meta.object_name
django.contrib.auth.models.DoesNotExist: User matching query does not exist.
Tue, 30 Oct 2018 17:36:43 simplelogger.py[line:28] ERROR User matching query does not exist.
Traceback (most recent call last):
  File "/Users/ethan/Documents/OneDrive/coding.net/doraemon_nirvana_lte/doraemon/business/ci/ci_task_queue_service.py", line 39, in start_user
    started_by = User.objects.get(id=ci_task_history.StartedBy)
  File "/Library/Frameworks/Python.framework/Versions/3.5/lib/python3.5/site-packages/django/db/models/manager.py", line 82, in manager_method
    return getattr(self.get_queryset(), name)(*args, **kwargs)
  File "/Library/Frameworks/Python.framework/Versions/3.5/lib/python3.5/site-packages/django/db/models/query.py", line 403, in get
    self.model._meta.object_name
django.contrib.auth.models.DoesNotExist: User matching query does not exist.
Tue, 30 Oct 2018 18:35:43 simplelogger.py[line:28] ERROR User matching query does not exist.
Traceback (most recent call last):
  File "/Users/ethan/Documents/OneDrive/coding.net/doraemon_nirvana_lte/doraemon/business/ci/ci_task_queue_service.py", line 39, in start_user
    started_by = User.objects.get(id=ci_task_history.StartedBy)
  File "/Library/Frameworks/Python.framework/Versions/3.5/lib/python3.5/site-packages/django/db/models/manager.py", line 82, in manager_method
    return getattr(self.get_queryset(), name)(*args, **kwargs)
  File "/Library/Frameworks/Python.framework/Versions/3.5/lib/python3.5/site-packages/django/db/models/query.py", line 403, in get
    self.model._meta.object_name
django.contrib.auth.models.DoesNotExist: User matching query does not exist.
Tue, 30 Oct 2018 18:35:43 simplelogger.py[line:28] ERROR User matching query does not exist.
Traceback (most recent call last):
  File "/Users/ethan/Documents/OneDrive/coding.net/doraemon_nirvana_lte/doraemon/business/ci/ci_task_queue_service.py", line 39, in start_user
    started_by = User.objects.get(id=ci_task_history.StartedBy)
  File "/Library/Frameworks/Python.framework/Versions/3.5/lib/python3.5/site-packages/django/db/models/manager.py", line 82, in manager_method
    return getattr(self.get_queryset(), name)(*args, **kwargs)
  File "/Library/Frameworks/Python.framework/Versions/3.5/lib/python3.5/site-packages/django/db/models/query.py", line 403, in get
    self.model._meta.object_name
django.contrib.auth.models.DoesNotExist: User matching query does not exist.
Wed, 31 Oct 2018 09:23:51 simplelogger.py[line:28] ERROR Project matching query does not exist.
Traceback (most recent call last):
  File "/Users/ethan/Documents/OneDrive/coding.net/doraemon_nirvana_lte/doraemon/model_managers/project_model_manager.py", line 198, in get
    result=super(ProjectManager,self).get_queryset().get(id=projectid)
  File "/Library/Frameworks/Python.framework/Versions/3.5/lib/python3.5/site-packages/django/db/models/query.py", line 403, in get
    self.model._meta.object_name
doraemon.project.models.DoesNotExist: Project matching query does not exist.
Wed, 31 Oct 2018 09:23:51 simplelogger.py[line:28] ERROR Project matching query does not exist.
Traceback (most recent call last):
  File "/Users/ethan/Documents/OneDrive/coding.net/doraemon_nirvana_lte/doraemon/model_managers/project_model_manager.py", line 198, in get
    result=super(ProjectManager,self).get_queryset().get(id=projectid)
  File "/Library/Frameworks/Python.framework/Versions/3.5/lib/python3.5/site-packages/django/db/models/query.py", line 403, in get
    self.model._meta.object_name
doraemon.project.models.DoesNotExist: Project matching query does not exist.
Wed, 31 Oct 2018 09:23:51 simplelogger.py[line:28] ERROR Project matching query does not exist.
Traceback (most recent call last):
  File "/Users/ethan/Documents/OneDrive/coding.net/doraemon_nirvana_lte/doraemon/model_managers/project_model_manager.py", line 198, in get
    result=super(ProjectManager,self).get_queryset().get(id=projectid)
  File "/Library/Frameworks/Python.framework/Versions/3.5/lib/python3.5/site-packages/django/db/models/query.py", line 403, in get
    self.model._meta.object_name
doraemon.project.models.DoesNotExist: Project matching query does not exist.
Wed, 31 Oct 2018 09:23:51 simplelogger.py[line:28] ERROR Project matching query does not exist.
Traceback (most recent call last):
  File "/Users/ethan/Documents/OneDrive/coding.net/doraemon_nirvana_lte/doraemon/model_managers/project_model_manager.py", line 198, in get
    result=super(ProjectManager,self).get_queryset().get(id=projectid)
  File "/Library/Frameworks/Python.framework/Versions/3.5/lib/python3.5/site-packages/django/db/models/query.py", line 403, in get
    self.model._meta.object_name
doraemon.project.models.DoesNotExist: Project matching query does not exist.
Wed, 31 Oct 2018 09:23:51 simplelogger.py[line:28] ERROR Project matching query does not exist.
Traceback (most recent call last):
  File "/Users/ethan/Documents/OneDrive/coding.net/doraemon_nirvana_lte/doraemon/model_managers/project_model_manager.py", line 198, in get
    result=super(ProjectManager,self).get_queryset().get(id=projectid)
  File "/Library/Frameworks/Python.framework/Versions/3.5/lib/python3.5/site-packages/django/db/models/query.py", line 403, in get
    self.model._meta.object_name
doraemon.project.models.DoesNotExist: Project matching query does not exist.
Wed, 31 Oct 2018 09:23:51 simplelogger.py[line:28] ERROR Project matching query does not exist.
Traceback (most recent call last):
  File "/Users/ethan/Documents/OneDrive/coding.net/doraemon_nirvana_lte/doraemon/model_managers/project_model_manager.py", line 198, in get
    result=super(ProjectManager,self).get_queryset().get(id=projectid)
  File "/Library/Frameworks/Python.framework/Versions/3.5/lib/python3.5/site-packages/django/db/models/query.py", line 403, in get
    self.model._meta.object_name
doraemon.project.models.DoesNotExist: Project matching query does not exist.
Wed, 31 Oct 2018 09:23:51 simplelogger.py[line:28] ERROR Project matching query does not exist.
Traceback (most recent call last):
  File "/Users/ethan/Documents/OneDrive/coding.net/doraemon_nirvana_lte/doraemon/model_managers/project_model_manager.py", line 198, in get
    result=super(ProjectManager,self).get_queryset().get(id=projectid)
  File "/Library/Frameworks/Python.framework/Versions/3.5/lib/python3.5/site-packages/django/db/models/query.py", line 403, in get
    self.model._meta.object_name
doraemon.project.models.DoesNotExist: Project matching query does not exist.
Wed, 31 Oct 2018 09:23:51 simplelogger.py[line:28] ERROR Project matching query does not exist.
Traceback (most recent call last):
  File "/Users/ethan/Documents/OneDrive/coding.net/doraemon_nirvana_lte/doraemon/model_managers/project_model_manager.py", line 198, in get
    result=super(ProjectManager,self).get_queryset().get(id=projectid)
  File "/Library/Frameworks/Python.framework/Versions/3.5/lib/python3.5/site-packages/django/db/models/query.py", line 403, in get
    self.model._meta.object_name
doraemon.project.models.DoesNotExist: Project matching query does not exist.
Wed, 31 Oct 2018 09:23:51 simplelogger.py[line:28] ERROR Project matching query does not exist.
Traceback (most recent call last):
  File "/Users/ethan/Documents/OneDrive/coding.net/doraemon_nirvana_lte/doraemon/model_managers/project_model_manager.py", line 198, in get
    result=super(ProjectManager,self).get_queryset().get(id=projectid)
  File "/Library/Frameworks/Python.framework/Versions/3.5/lib/python3.5/site-packages/django/db/models/query.py", line 403, in get
    self.model._meta.object_name
doraemon.project.models.DoesNotExist: Project matching query does not exist.
Wed, 31 Oct 2018 09:23:51 simplelogger.py[line:28] ERROR Project matching query does not exist.
Traceback (most recent call last):
  File "/Users/ethan/Documents/OneDrive/coding.net/doraemon_nirvana_lte/doraemon/model_managers/project_model_manager.py", line 198, in get
    result=super(ProjectManager,self).get_queryset().get(id=projectid)
  File "/Library/Frameworks/Python.framework/Versions/3.5/lib/python3.5/site-packages/django/db/models/query.py", line 403, in get
    self.model._meta.object_name
doraemon.project.models.DoesNotExist: Project matching query does not exist.
Wed, 31 Oct 2018 09:23:51 simplelogger.py[line:28] ERROR Project matching query does not exist.
Traceback (most recent call last):
  File "/Users/ethan/Documents/OneDrive/coding.net/doraemon_nirvana_lte/doraemon/model_managers/project_model_manager.py", line 198, in get
    result=super(ProjectManager,self).get_queryset().get(id=projectid)
  File "/Library/Frameworks/Python.framework/Versions/3.5/lib/python3.5/site-packages/django/db/models/query.py", line 403, in get
    self.model._meta.object_name
doraemon.project.models.DoesNotExist: Project matching query does not exist.
